<robot name="research_humanoid">

<link name="torso"/>
<link name="left_thigh"/>
<link name="left_shin"/>
<link name="left_foot"/>

<link name="right_thigh"/>
<link name="right_shin"/>
<link name="right_foot"/>

<joint name="left_hip" type="revolute">
<parent link="torso"/>
<child link="left_thigh"/>
<origin xyz="0 0.1 -0.1"/>
<axis xyz="1 0 0"/>
</joint>

<joint name="left_knee" type="revolute">
<parent link="left_thigh"/>
<child link="left_shin"/>
<origin xyz="0 0 -0.4"/>
<axis xyz="1 0 0"/>
</joint>

<joint name="left_ankle" type="revolute">
<parent link="left_shin"/>
<child link="left_foot"/>
<origin xyz="0 0 -0.4"/>
<axis xyz="1 0 0"/>
</joint>

<joint name="right_hip" type="revolute">
<parent link="torso"/>
<child link="right_thigh"/>
<origin xyz="0 -0.1 -0.1"/>
<axis xyz="1 0 0"/>
</joint>

<joint name="right_knee" type="revolute">
<parent link="right_thigh"/>
<child link="right_shin"/>
<origin xyz="0 0 -0.4"/>
<axis xyz="1 0 0"/>
</joint>

<joint name="right_ankle" type="revolute">
<parent link="right_shin"/>
<child link="right_foot"/>
<origin xyz="0 0 -0.4"/>
<axis xyz="1 0 0"/>
</joint>

</robot>